2025-06-05 15:03:10.12
fdbc0987
User
The above exception was the direct cause of the following exception:
2025-06-05 15:03:10.12
fdbc0987
User
2025-06-05 15:03:10.12
fdbc0987
User
Traceback (most recent call last):
2025-06-05 15:03:10.12
fdbc0987
User
File "/home/runner/workspace/.pythonlibs/lib/python3.11/site-packages/django/core/handlers/exception.py", line 55, in inner
2025-06-05 15:03:10.12
fdbc0987
User
response = get_response(request)
2025-06-05 15:03:10.12
fdbc0987
User
^^^^^^^^^^^^^^^^^^^^^
2025-06-05 15:03:10.12
fdbc0987
User
File "/home/runner/workspace/.pythonlibs/lib/python3.11/site-packages/django/core/handlers/base.py", line 197, in _get_response
2025-06-05 15:03:10.12
fdbc0987
User
response = wrapped_callback(request, *callback_args, **callback_kwargs)
2025-06-05 15:03:10.12
fdbc0987
User
^^^^^^^^^^^^^^^^^^^^^^^^^^^^^^^^^^^^^^^^^^^^^^^^^^^^^^^^^^^^
2025-06-05 15:03:10.12
fdbc0987
User
File "/home/runner/workspace/critique/views.py", line 22, in index
2025-06-05 15:03:10.12
fdbc0987
User
artwork_count = ArtWork.objects.count()
2025-06-05 15:03:10.12
fdbc0987
User
^^^^^^^^^^^^^^^^^^^^^^^
2025-06-05 15:03:10.12
fdbc0987
User
File "/home/runner/workspace/.pythonlibs/lib/python3.11/site-packages/django/db/models/manager.py", line 87, in manager_method
2025-06-05 15:03:10.12
fdbc0987
User
return getattr(self.get_queryset(), name)(*args, **kwargs)
2025-06-05 15:03:10.12
fdbc0987
User
^^^^^^^^^^^^^^^^^^^^^^^^^^^^^^^^^^^^^^^^^^^^^^^^^^^
2025-06-05 15:03:10.12
fdbc0987
User
File "/home/runner/workspace/.pythonlibs/lib/python3.11/site-packages/django/db/models/query.py", line 604, in count
2025-06-05 15:03:10.12
fdbc0987
User
return self.query.get_count(using=self.db)
2025-06-05 15:03:10.12
fdbc0987
User
^^^^^^^^^^^^^^^^^^^^^^^^^^^^^^^^^^^
2025-06-05 15:03:10.12
fdbc0987
User
File "/home/runner/workspace/.pythonlibs/lib/python3.11/site-packages/django/db/models/sql/query.py", line 644, in get_count
2025-06-05 15:03:10.12
fdbc0987
User
return obj.get_aggregation(using, {"__count": Count("*")})["__count"]
2025-06-05 15:03:10.12
fdbc0987
User
^^^^^^^^^^^^^^^^^^^^^^^^^^^^^^^^^^^^^^^^^^^^^^^^^^^
2025-06-05 15:03:10.12
fdbc0987
User
File "/home/runner/workspace/.pythonlibs/lib/python3.11/site-packages/django/db/models/sql/query.py", line 626, in get_aggregation
2025-06-05 15:03:10.12
fdbc0987
User
result = compiler.execute_sql(SINGLE)
