2025-06-05 15:03:10.12
fdbc0987
User
^^^^^^^^^^^^^^^^^^^^^^^^^^^^^^^^^^^^^^^^^^^^^^^^^^^
2025-06-05 15:03:10.12
fdbc0987
User
File "/home/runner/workspace/.pythonlibs/lib/python3.11/site-packages/django/db/models/sql/query.py", line 626, in get_aggregation
2025-06-05 15:03:10.12
fdbc0987
User
result = compiler.execute_sql(SINGLE)
2025-06-05 15:03:10.12
fdbc0987
User
^^^^^^^^^^^^^^^^^^^^^^^^^^^^
2025-06-05 15:03:10.12
fdbc0987
User
File "/home/runner/workspace/.pythonlibs/lib/python3.11/site-packages/django/db/models/sql/compiler.py", line 1621, in execute_sql
2025-06-05 15:03:10.12
fdbc0987
User
cursor = self.connection.cursor()
2025-06-05 15:03:10.12
fdbc0987
User
^^^^^^^^^^^^^^^^^^^^^^^^
2025-06-05 15:03:10.12
fdbc0987
User
File "/home/runner/workspace/.pythonlibs/lib/python3.11/site-packages/django/utils/asyncio.py", line 26, in inner
2025-06-05 15:03:10.12
fdbc0987
User
return func(*args, **kwargs)
2025-06-05 15:03:10.12
fdbc0987
User
^^^^^^^^^^^^^^^^^^^^^
2025-06-05 15:03:10.12
fdbc0987
User
File "/home/runner/workspace/.pythonlibs/lib/python3.11/site-packages/django/db/backends/base/base.py", line 320, in cursor
2025-06-05 15:03:10.12
fdbc0987
User
return self._cursor()
2025-06-05 15:03:10.12
fdbc0987
User
^^^^^^^^^^^^^^
2025-06-05 15:03:10.12
fdbc0987
User
File "/home/runner/workspace/.pythonlibs/lib/python3.11/site-packages/django/db/backends/base/base.py", line 296, in _cursor
2025-06-05 15:03:10.12
fdbc0987
User
self.ensure_connection()
2025-06-05 15:03:10.12
fdbc0987
User
File "/home/runner/workspace/.pythonlibs/lib/python3.11/site-packages/django/utils/asyncio.py", line 26, in inner
2025-06-05 15:03:10.12
fdbc0987
User
return func(*args, **kwargs)
2025-06-05 15:03:10.12
fdbc0987
User
^^^^^^^^^^^^^^^^^^^^^
2025-06-05 15:03:10.12
fdbc0987
User
File "/home/runner/workspace/.pythonlibs/lib/python3.11/site-packages/django/db/backends/base/base.py", line 278, in ensure_connection
2025-06-05 15:03:10.12
fdbc0987
User
with self.wrap_database_errors:
2025-06-05 15:03:10.12
fdbc0987
User
File "/home/runner/workspace/.pythonlibs/lib/python3.11/site-packages/django/db/utils.py", line 91, in __exit__
2025-06-05 15:03:10.12
fdbc0987
User
raise dj_exc_value.with_traceback(traceback) from exc_value
2025-06-05 15:03:10.12
fdbc0987
User
File "/home/runner/workspace/.pythonlibs/lib/python3.11/site-packages/django/db/backends/base/base.py", line 279, in ensure_connection
2025-06-05 15:03:10.12
fdbc0987
User
self.connect()
2025-06-05 15:03:10.12
fdbc0987
User
File "/home/runner/workspace/.pythonlibs/lib/python3.11/site-packages/django/utils/asyncio.py", line 26, in inner
2025-06-05 15:03:10.12
fdbc0987
User
return func(*args, **kwargs)
2025-06-05 15:03:10.12
fdbc0987
User
^^^^^^^^^^^^^^^^^^^^^
2025-06-05 15:03:10.12
fdbc0987
User
File "/home/runner/workspace/.pythonlibs/lib/python3.11/site-packages/django/db/backends/base/base.py", line 256, in connect
2025-06-05 15:03:10.12
fdbc0987
User
self.connection = self.get_new_connection(conn_params)
2025-06-05 15:03:10.12
fdbc0987
User
^^^^^^^^^^^^^^^^^^^^^^^^^^^^^^^^^^^^
2025-06-05 15:03:10.12
fdbc0987
User
File "/home/runner/workspace/.pythonlibs/lib/python3.11/site-packages/django/utils/asyncio.py", line 26, in inner
2025-06-05 15:03:10.12
fdbc0987
User
return func(*args, **kwargs)
2025-06-05 15:03:10.12
fdbc0987
User
^^^^^^^^^^^^^^^^^^^^^
2025-06-05 15:03:10.12
fdbc0987
User
File "/home/runner/workspace/.pythonlibs/lib/python3.11/site-packages/django/db/backends/postgresql/base.py", line 332, in get_new_connection
2025-06-05 15:03:10.12
fdbc0987
User
connection = self.Database.connect(**conn_params)
2025-06-05 15:03:10.12
fdbc0987
User
^^^^^^^^^^^^^^^^^^^^^^^^^^^^^^^^^^^^
2025-06-05 15:03:10.12
fdbc0987
User
File "/home/runner/workspace/.pythonlibs/lib/python3.11/site-packages/psycopg2/__init__.py", line 122, in connect
2025-06-05 15:03:10.12
fdbc0987
User
conn = _connect(dsn, connection_factory=connection_factory, **kwasync)
2025-06-05 15:03:10.12
fdbc0987
User
^^^^^^^^^^^^^^^^^^^^^^^^^^^^^^^^^^^^^^^^^^^^^^^^^^^^^^^^^^^^^^^
2025-06-05 15:03:10.12
fdbc0987
User
django.db.utils.OperationalError: connection to server at "ep-round-mountain-a5clrkjq.us-east-2.aws.neon.tech" (2600:1f16:12b2:b40a:533d:22ad:38c2:f393), port 5432 failed: ERROR: Control plane request failed
